<?xml version="1.0" encoding="UTF-8"?>
<!-- Generated by org.testng.reporters.JUnitReportReporter -->
<testsuite skipped="0" hostname="DESKTOP-0OHGDCN" name="assignment11.TestNg_Assignment10" tests="8" failures="1" timestamp="07 Feb 2023 15:58:49 GMT" time="59.085" errors="0">
  <testcase name="Login" time="5.725" classname="assignment11.TestNg_Assignment10"/>
  <testcase name="Login" time="5.494" classname="assignment11.TestNg_Assignment10"/>
  <testcase name="CreateCourse" time="13.163" classname="assignment11.TestNg_Assignment10"/>
  <testcase name="CreateCourse" time="12.638" classname="assignment11.TestNg_Assignment10"/>
  <testcase name="Delete" time="10.189" classname="assignment11.TestNg_Assignment10">
    <failure type="java.lang.AssertionError" message="expected not same [3] but found [3]">
      <![CDATA[java.lang.AssertionError: expected not same [3] but found [3]
at org.testng.Assert.fail(Assert.java:96)
at org.testng.Assert.failSame(Assert.java:764)
at org.testng.Assert.assertNotSame(Assert.java:745)
at org.testng.Assert.assertNotSame(Assert.java:756)
at assignment11.TestNg_Assignment10.Delete(TestNg_Assignment10.java:151)
at sun.reflect.NativeMethodAccessorImpl.invoke0(Native Method)
at sun.reflect.NativeMethodAccessorImpl.invoke(Unknown Source)
at sun.reflect.DelegatingMethodAccessorImpl.invoke(Unknown Source)
at java.lang.reflect.Method.invoke(Unknown Source)
at org.testng.internal.MethodInvocationHelper.invokeMethod(MethodInvocationHelper.java:124)
at org.testng.internal.Invoker.invokeMethod(Invoker.java:583)
at org.testng.internal.Invoker.invokeTestMethod(Invoker.java:719)
at org.testng.internal.Invoker.invokeTestMethods(Invoker.java:989)
at org.testng.internal.TestMethodWorker.invokeTestMethods(TestMethodWorker.java:125)
at org.testng.internal.TestMethodWorker.run(TestMethodWorker.java:109)
at org.testng.TestRunner.privateRun(TestRunner.java:648)
at org.testng.TestRunner.run(TestRunner.java:505)
at org.testng.SuiteRunner.runTest(SuiteRunner.java:455)
at org.testng.SuiteRunner.access$000(SuiteRunner.java:40)
at org.testng.SuiteRunner$SuiteWorker.run(SuiteRunner.java:489)
at org.testng.internal.thread.ThreadUtil$1.call(ThreadUtil.java:52)
at java.util.concurrent.FutureTask.run(Unknown Source)
at java.util.concurrent.ThreadPoolExecutor.runWorker(Unknown Source)
at java.util.concurrent.ThreadPoolExecutor$Worker.run(Unknown Source)
at java.lang.Thread.run(Unknown Source)
]]>
    </failure>
  </testcase> <!-- Delete -->
  <testcase name="Delete" time="10.208" classname="assignment11.TestNg_Assignment10"/>
  <testcase name="tearDown" time="0.812" classname="assignment11.TestNg_Assignment10"/>
  <testcase name="tearDown" time="0.856" classname="assignment11.TestNg_Assignment10"/>
</testsuite> <!-- assignment11.TestNg_Assignment10 -->
